<sdf version='1.9'>
  <model name='leg7'>
    <link name='base'>
      <sensor name="imu_sensor" type="imu">
        <always_on>1</always_on>
        <update_rate>1000</update_rate>
        <visualize>true</visualize>
        <topic>base_imu</topic>
      </sensor>
      <inertial>
        <pose>-7.027e-14 -3.9404e-13 0.058682 0 0 0</pose>
        <mass>16.0</mass>
        <inertia
          ixx="0.329343"
          ixy="0.000022"
          ixz="0"
          iyy="0.156277"
          iyz="0"
          izz="0.304508" />
      </inertial>
      <collision name='base_collision'>
        <pose>0 0 0 0 0 0</pose>
        <geometry>
          <mesh>
            <scale>1 1 1</scale>
            <uri>model://leg_description/meshes/base.STL</uri>
          </mesh>
        </geometry>
      </collision>
      <visual name='base_visual'>
        <pose>0 0 0 0 0 0</pose>
        <geometry>
          <mesh>
            <scale>1 1 1</scale>
            <uri>model://leg_description/meshes/base.STL</uri>
          </mesh>
        </geometry>
        <material>
          <diffuse>0.9902 1 1 1</diffuse>
          <ambient>0.9902 1 1 1</ambient>
        </material>
      </visual>
    </link>
    <joint name='L_hip_joint' type='revolute'>
      <pose relative_to='base'>0 0.12 -0.057 0 0 0</pose>
      <parent>base</parent>
      <child>L_hip</child>
      <axis>
        <xyz>0 0 1</xyz>
        <limit>
          <lower>-1.5</lower>
          <upper>1.5</upper>
          <effort>50</effort>
          <velocity>50</velocity>
        </limit>
        <dynamics>
          <spring_reference>0</spring_reference>
          <spring_stiffness>0</spring_stiffness>
        </dynamics>
      </axis>
    </joint>
    <link name='L_hip'>
      <pose relative_to='L_hip_joint'>0 0 0 0 0 0</pose>
      <inertial>
        <pose>-0.093816 -5.9543e-05 -0.064188 0 0 0</pose>
        <mass>1.3589</mass>
        <inertia>
          <ixx>0.0020690000000000001</ixx>
          <ixy>-2.7099999999999999e-06</ixy>
          <ixz>-0.00041399999999999998</ixz>
          <iyy>0.00199</iyy>
          <iyz>-2.6e-07</iyz>
          <izz>0.0015047999999999999</izz>
        </inertia>
      </inertial>
      <visual name='L_hip_visual'>
        <pose>0 0 0 0 0 0</pose>
        <geometry>
          <mesh>
            <scale>1 1 1</scale>
            <uri>model://leg_description/meshes/L_hip.STL</uri>
          </mesh>
        </geometry>
        <material>
          <diffuse>0.9902 1 1 1</diffuse>
          <ambient>0.9902 1 1 1</ambient>
        </material>
      </visual>
    </link>
    <joint name='L_hip2_joint' type='revolute'>
      <pose relative_to='L_hip'>-0.0633 0 -0.07000000000000001 0 0 0</pose>
      <parent>L_hip</parent>
      <child>L_hip2</child>
      <axis>
        <xyz>1 0 0</xyz>
        <limit>
          <lower>-0.5</lower>
          <upper>1</upper>
          <effort>50</effort>
          <velocity>50</velocity>
        </limit>
        <dynamics>
          <spring_reference>0</spring_reference>
          <spring_stiffness>0</spring_stiffness>
        </dynamics>
      </axis>
    </joint>
    <link name='L_hip2'>
      <pose relative_to='L_hip2_joint'>0 0 0 0 0 0</pose>
      <inertial>
        <pose>0.059646 -0.064582 5.875e-05 0 0 0</pose>
        <mass>1.3255999999999999</mass>
        <inertia>
          <ixx>0.001232</ixx>
          <ixy>0.00022000000000000001</ixy>
          <ixz>6.3e-07</ixz>
          <iyy>0.0018190000000000001</iyy>
          <iyz>2.4399999999999999e-06</iyz>
          <izz>0.0015150000000000001</izz>
        </inertia>
      </inertial>
      <visual name='L_hip2_visual'>
        <pose>0 0 0 0 0 0</pose>
        <geometry>
          <mesh>
            <scale>1 1 1</scale>
            <uri>model://leg_description/meshes/L_hip2.STL</uri>
          </mesh>
        </geometry>
        <material>
          <diffuse>0.9902 1 1 1</diffuse>
          <ambient>0.9902 1 1 1</ambient>
        </material>
      </visual>
    </link>
    <joint name='L_thigh_joint' type='revolute'>
      <pose relative_to='L_hip2'>0.0633 0 0 0 0 0</pose>
      <parent>L_hip2</parent>
      <child>L_thigh</child>
      <axis>
        <xyz>0 1 0</xyz>
        <limit>
          <lower>-1.7</lower>
          <upper>0</upper>
          <effort>100</effort>
          <velocity>50</velocity>
        </limit>
        <dynamics>
          <spring_reference>0</spring_reference>
          <spring_stiffness>0</spring_stiffness>
        </dynamics>
      </axis>
    </joint>
    <link name='L_thigh'>
      <pose relative_to='L_thigh_joint'>0 0 0 0 0 0</pose>
      <inertial>
        <pose>-4.3348e-13 0.00035614 -0.11733 0 0 0</pose>
        <mass>3.2999999999999998</mass>
        <inertia>
          <ixx>0.054972</ixx>
          <ixy>6.9999999999999999e-06</ixy>
          <ixz>5.0000000000000004e-06</ixz>
          <iyy>0.051520000000000003</iyy>
          <iyz>-0.0050959999999999998</iyz>
          <izz>0.0079729999999999992</izz>
        </inertia>
      </inertial>
      <visual name='L_thigh_visual'>
        <pose>0 0 0 0 0 0</pose>
        <geometry>
          <mesh>
            <scale>1 1 1</scale>
            <uri>model://leg_description/meshes/L_thigh.STL</uri>
          </mesh>
        </geometry>
        <material>
          <diffuse>0.9902 1 1 1</diffuse>
          <ambient>0.9902 1 1 1</ambient>
        </material>
      </visual>
    </link>
    <joint name='L_calf_joint' type='revolute'>
      <pose relative_to='L_thigh'>0 0 -0.35 0 0 0</pose>
      <parent>L_thigh</parent>
      <child>L_calf</child>
      <axis>
        <xyz>0 1 0</xyz>
        <limit>
          <lower>0</lower>
          <upper>2</upper>
          <effort>250</effort>
          <velocity>50</velocity>
        </limit>
        <dynamics>
          <spring_reference>0</spring_reference>
          <spring_stiffness>0</spring_stiffness>
        </dynamics>
      </axis>
    </joint>
    <link name='L_calf'>
      <pose relative_to='L_calf_joint'>0 0 0 0 0 0</pose>
      <inertial>
        <pose>0 0 -0.18354 0 0 0</pose>
        <mass>0.75</mass>
        <inertia>
          <ixx>0.010954999999999999</ixx>
          <ixy>0</ixy>
          <ixz>0</ixz>
          <iyy>0.010865</iyy>
          <iyz>0</iyz>
          <izz>0.00061399999999999996</izz>
        </inertia>
      </inertial>
      <visual name='L_calf_visual'>
        <pose>0 0 0 0 0 0</pose>
        <geometry>
          <mesh>
            <scale>1 1 1</scale>
            <uri>model://leg_description/meshes/L_calf.STL</uri>
          </mesh>
        </geometry>
        <material>
          <diffuse>1 1 1 1</diffuse>
          <ambient>1 1 1 1</ambient>
        </material>
      </visual>
    </link>
    <joint name='L_toe_joint' type='revolute'>
      <pose relative_to='L_calf'>0 0 -0.35 0 0 0</pose>
      <parent>L_calf</parent>
      <child>L_toe</child>
      <axis>
        <xyz>0 1 0</xyz>
        <limit>
          <lower>-0.80000000000000004</lower>
          <upper>0.80000000000000004</upper>
          <effort>100</effort>
          <velocity>50</velocity>
        </limit>
        <dynamics>
          <spring_reference>0</spring_reference>
          <spring_stiffness>0</spring_stiffness>
        </dynamics>
      </axis>
    </joint>
    <link name='L_toe'>
      <pose relative_to='L_toe_joint'>0 0 0 0 0 0</pose>
      <inertial>
        <pose>0.016891 0 -0.018446 0 0 0</pose>
        <mass>0.40000000000000002</mass>
        <inertia>
          <ixx>0.000165</ixx>
          <ixy>0</ixy>
          <ixz>7.7999999999999999e-05</ixz>
          <iyy>0.00097900000000000005</iyy>
          <iyz>0</iyz>
          <izz>0.00092000000000000003</izz>
        </inertia>
      </inertial>
      <collision name='L_toe_collision'>
        <pose>0 0 0 0 0 0</pose>
        <geometry>
          <mesh>
            <scale>1 1 1</scale>
            <uri>model://leg_description/meshes/L_toe.STL</uri>
          </mesh>
        </geometry>
        <friction>
          <ode>
            <mu>0.8</mu>
            <mu2>0.9</mu2>
          </ode>
        </friction>
      </collision>
      <visual name='L_toe_visual'>
        <pose>0 0 0 0 0 0</pose>
        <geometry>
          <mesh>
            <scale>1 1 1</scale>
            <uri>model://leg_description/meshes/L_toe.STL</uri>
          </mesh>
        </geometry>
        <material>
          <diffuse>1 1 1 1</diffuse>
          <ambient>1 1 1 1</ambient>
        </material>
      </visual>
    </link>
    <joint name='R_hip_joint' type='revolute'>
      <pose relative_to='base'>0 -0.12 -0.057 0 0 0</pose>
      <parent>base</parent>
      <child>R_hip</child>
      <axis>
        <xyz>0 0 1</xyz>
        <limit>
          <lower>-1.5</lower>
          <upper>1.5</upper>
          <effort>50</effort>
          <velocity>50</velocity>
        </limit>
        <dynamics>
          <spring_reference>0</spring_reference>
          <spring_stiffness>0</spring_stiffness>
        </dynamics>
      </axis>
    </joint>
    <link name='R_hip'>
      <pose relative_to='R_hip_joint'>0 0 0 0 0 0</pose>
      <inertial>
        <pose>-0.093816 -5.9543e-05 -0.064188 0 0 0</pose>
        <mass>1.3589</mass>
        <inertia>
          <ixx>0.0020690000000000001</ixx>
          <ixy>-2.7099999999999999e-06</ixy>
          <ixz>-0.00041399999999999998</ixz>
          <iyy>0.00199</iyy>
          <iyz>-2.6e-07</iyz>
          <izz>0.0015047999999999999</izz>
        </inertia>
      </inertial>
      <visual name='R_hip_visual'>
        <pose>0 0 0 0 0 0</pose>
        <geometry>
          <mesh>
            <scale>1 1 1</scale>
            <uri>model://leg_description/meshes/R_hip.STL</uri>
          </mesh>
        </geometry>
        <material>
          <diffuse>0.9902 1 1 1</diffuse>
          <ambient>0.9902 1 1 1</ambient>
        </material>
      </visual>
    </link>
    <joint name='R_hip2_joint' type='revolute'>
      <pose relative_to='R_hip'>-0.0633 0 -0.07000000000000001 0 0 0</pose>
      <parent>R_hip</parent>
      <child>R_hip2</child>
      <axis>
        <xyz>1 0 0</xyz>
        <limit>
          <lower>-1</lower>
          <upper>0.5</upper>
          <effort>50</effort>
          <velocity>50</velocity>
        </limit>
        <dynamics>
          <spring_reference>0</spring_reference>
          <spring_stiffness>0</spring_stiffness>
        </dynamics>
      </axis>
    </joint>
    <link name='R_hip2'>
      <pose relative_to='R_hip2_joint'>0 0 0 0 0 0</pose>
      <inertial>
        <pose>0.05961 0.064582 5.875e-05 0 0 0</pose>
        <mass>1.3255999999999999</mass>
        <inertia>
          <ixx>0.001232</ixx>
          <ixy>-0.00022000000000000001</ixy>
          <ixz>-9.9999999999999995e-07</ixz>
          <iyy>0.0018190000000000001</iyy>
          <iyz>-1.9999999999999999e-06</iyz>
          <izz>0.0015150000000000001</izz>
        </inertia>
      </inertial>
      <visual name='R_hip2_visual'>
        <pose>0 0 0 0 0 0</pose>
        <geometry>
          <mesh>
            <scale>1 1 1</scale>
            <uri>model://leg_description/meshes/R_hip2.STL</uri>
          </mesh>
        </geometry>
        <material>
          <diffuse>0.9902 1 1 1</diffuse>
          <ambient>0.9902 1 1 1</ambient>
        </material>
      </visual>
    </link>
    <joint name='R_thigh_joint' type='revolute'>
      <pose relative_to='R_hip2'>0.0633 0 0 0 0 0</pose>
      <parent>R_hip2</parent>
      <child>R_thigh</child>
      <axis>
        <xyz>0 1 0</xyz>
        <limit>
          <lower>-1.7</lower>
          <upper>0</upper>
          <effort>100</effort>
          <velocity>50</velocity>
        </limit>
        <dynamics>
          <spring_reference>0</spring_reference>
          <spring_stiffness>0</spring_stiffness>
        </dynamics>
      </axis>
    </joint>
    <link name='R_thigh'>
      <pose relative_to='R_thigh_joint'>0 0 0 0 0 0</pose>
      <inertial>
        <pose>1.4759e-14 -0.00035614 -0.11733 0 0 0</pose>
        <mass>3.2999999999999998</mass>
        <inertia>
          <ixx>0.054972</ixx>
          <ixy>6.9999999999999999e-06</ixy>
          <ixz>-5.0000000000000004e-06</ixz>
          <iyy>0.051520000000000003</iyy>
          <iyz>0.0050959999999999998</iyz>
          <izz>0.0079729999999999992</izz>
        </inertia>
      </inertial>
      <visual name='R_thigh_visual'>
        <pose>0 0 0 0 0 0</pose>
        <geometry>
          <mesh>
            <scale>1 1 1</scale>
            <uri>model://leg_description/meshes/R_thigh.STL</uri>
          </mesh>
        </geometry>
        <material>
          <diffuse>0.9902 1 1 1</diffuse>
          <ambient>0.9902 1 1 1</ambient>
        </material>
      </visual>
    </link>
    <joint name='R_calf_joint' type='revolute'>
      <pose relative_to='R_thigh'>0 0 -0.35 0 0 0</pose>
      <parent>R_thigh</parent>
      <child>R_calf</child>
      <axis>
        <xyz>0 1 0</xyz>
        <limit>
          <lower>0</lower>
          <upper>2</upper>
          <effort>250</effort>
          <velocity>50</velocity>
        </limit>
        <dynamics>
          <spring_reference>0</spring_reference>
          <spring_stiffness>0</spring_stiffness>
        </dynamics>
      </axis>
    </joint>
    <link name='R_calf'>
      <pose relative_to='R_calf_joint'>0 0 0 0 0 0</pose>
      <inertial>
        <pose>0 0 -0.18354 0 0 0</pose>
        <mass>0.75</mass>
        <inertia>
          <ixx>0.010954999999999999</ixx>
          <ixy>0</ixy>
          <ixz>0</ixz>
          <iyy>0.010865</iyy>
          <iyz>0</iyz>
          <izz>0.00061399999999999996</izz>
        </inertia>
      </inertial>
      <visual name='R_calf_visual'>
        <pose>0 0 0 0 0 0</pose>
        <geometry>
          <mesh>
            <scale>1 1 1</scale>
            <uri>model://leg_description/meshes/R_calf.STL</uri>
          </mesh>
        </geometry>
        <material>
          <diffuse>1 1 1 1</diffuse>
          <ambient>1 1 1 1</ambient>
        </material>
      </visual>
    </link>
    <joint name='R_toe_joint' type='revolute'>
      <pose relative_to='R_calf'>0 0 -0.35 0 0 0</pose>
      <parent>R_calf</parent>
      <child>R_toe</child>
      <axis>
        <xyz>0 1 0</xyz>
        <limit>
          <lower>-0.80000000000000004</lower>
          <upper>0.80000000000000004</upper>
          <effort>100</effort>
          <velocity>50</velocity>
        </limit>
        <dynamics>
          <spring_reference>0</spring_reference>
          <spring_stiffness>0</spring_stiffness>
        </dynamics>
      </axis>
    </joint>
    <link name='R_toe'>
      <pose relative_to='R_toe_joint'>0 0 0 0 0 0</pose>
      <inertial>
        <pose>0.016891 0 -0.018446 0 0 0</pose>
        <mass>0.40000000000000002</mass>
        <inertia>
          <ixx>0.000165</ixx>
          <ixy>0</ixy>
          <ixz>7.7999999999999999e-05</ixz>
          <iyy>0.00097900000000000005</iyy>
          <iyz>0</iyz>
          <izz>0.00092000000000000003</izz>
        </inertia>
      </inertial>
      <collision name='R_toe_collision'>
        <pose>0 0 0 0 0 0</pose>
        <geometry>
          <mesh>
            <scale>1 1 1</scale>
            <uri>model://leg_description/meshes/R_toe.STL</uri>
          </mesh>
        </geometry>
                <surface>
        <friction>
          <ode>
            <mu>0.8</mu>
            <mu2>0.9</mu2>
          </ode>
        </friction>
      </surface>
      </collision>
      <visual name='R_toe_visual'>
        <pose>0 0 0 0 0 0</pose>
        <geometry>
          <mesh>
            <scale>1 1 1</scale>
            <uri>model://leg_description/meshes/R_toe.STL</uri>
          </mesh>
        </geometry>
        <material>
          <diffuse>1 1 1 1</diffuse>
          <ambient>1 1 1 1</ambient>
        </material>
      </visual>
    </link>

    <plugin
      filename="ignition-gazebo-apply-joint-force-system"
      name="gz::sim::systems::ApplyJointForce">
      <joint_name>R_hip_joint</joint_name>
    </plugin>

    <plugin
      filename="ignition-gazebo-apply-joint-force-system"
      name="gz::sim::systems::ApplyJointForce">
      <joint_name>R_hip2_joint</joint_name>
    </plugin>  

    <plugin
      filename="ignition-gazebo-apply-joint-force-system"
      name="gz::sim::systems::ApplyJointForce">
      <joint_name>R_thigh_joint</joint_name>
    </plugin>  

    <plugin
      filename="ignition-gazebo-apply-joint-force-system"
      name="gz::sim::systems::ApplyJointForce">
      <joint_name>R_toe_joint</joint_name>
    </plugin>  

    <plugin
      filename="ignition-gazebo-apply-joint-force-system"
      name="gz::sim::systems::ApplyJointForce">
      <joint_name>L_hip_joint</joint_name>
    </plugin>  

    <plugin
      filename="ignition-gazebo-apply-joint-force-system"
      name="gz::sim::systems::ApplyJointForce">
      <joint_name>L_hip2_joint</joint_name>
    </plugin>  

    <plugin
      filename="ignition-gazebo-apply-joint-force-system"
      name="gz::sim::systems::ApplyJointForce">
      <joint_name>L_thigh_joint</joint_name>
    </plugin>  

    <plugin
      filename="ignition-gazebo-apply-joint-force-system"
      name="gz::sim::systems::ApplyJointForce">
      <joint_name>L_calf_joint</joint_name>
    </plugin>  

    <plugin
      filename="ignition-gazebo-apply-joint-force-system"
      name="gz::sim::systems::ApplyJointForce">
      <joint_name>L_toe_joint</joint_name>
    </plugin>  

  </model>
</sdf>
